x----------------------------------------------------------------------
[[52842,1],4]: A high-performance Open MPI point-to-point messaging module
was unable to find any relevant network interfaces:

Module: OpenFabrics (openib)
  Host: bastet

Another transport will be used instead, although this may result in
lower performance.

NOTE: You can disable this warning by setting the MCA parameter
btl_base_warn_component_unused to 0.
--------------------------------------------------------------------------
Traceback (most recent call last):
  File "/usr/lib/python3.6/runpy.py", line 193, in _run_module_as_main
    "__main__", mod_spec)
  File "/usr/lib/python3.6/runpy.py", line 85, in _run_code
    exec(code, run_globals)
  File "/usr/local/lib/python3.6/dist-packages/mpi4py/__main__.py", line 7, in <module>
    main()
  File "/usr/local/lib/python3.6/dist-packages/mpi4py/run.py", line 196, in main
    run_command_line(args)
  File "/usr/local/lib/python3.6/dist-packages/mpi4py/run.py", line 47, in run_command_line
    run_path(sys.argv[0], run_name='__main__')
  File "/usr/lib/python3.6/runpy.py", line 263, in run_path
    pkg_name=pkg_name, script_name=fname)
  File "/usr/lib/python3.6/runpy.py", line 96, in _run_module_code
    mod_name, mod_spec, pkg_name, script_name)
  File "/usr/lib/python3.6/runpy.py", line 85, in _run_code
    exec(code, run_globals)
  File "ga_wrapper.py", line 151, in <module>
    myFitness=getFitness(data,numStochasticReplicates,myIP)
  File "ga_wrapper.py", line 45, in getFitness
    fitness=np.zeros()
TypeError: Required argument 'shape' (pos 1) not found
Traceback (most recent call last):
  File "/usr/lib/python3.6/runpy.py", line 193, in _run_module_as_main
    "__main__", mod_spec)
  File "/usr/lib/python3.6/runpy.py", line 85, in _run_code
    exec(code, run_globals)
  File "/usr/local/lib/python3.6/dist-packages/mpi4py/__main__.py", line 7, in <module>
    main()
  File "/usr/local/lib/python3.6/dist-packages/mpi4py/run.py", line 196, in main
    run_command_line(args)
  File "/usr/local/lib/python3.6/dist-packages/mpi4py/run.py", line 47, in run_command_line
    run_path(sys.argv[0], run_name='__main__')
  File "/usr/lib/python3.6/runpy.py", line 263, in run_path
    pkg_name=pkg_name, script_name=fname)
  File "/usr/lib/python3.6/runpy.py", line 96, in _run_module_code
    mod_name, mod_spec, pkg_name, script_name)
  File "/usr/lib/python3.6/runpy.py", line 85, in _run_code
    exec(code, run_globals)
  File "ga_wrapper.py", line 151, in <module>
    myFitness=getFitness(data,numStochasticReplicates,myIP)
  File "ga_wrapper.py", line 45, in getFitness
    fitness=np.zeros()
TypeError: Required argument 'shape' (pos 1) not found
Traceback (most recent call last):
  File "/usr/lib/python3.6/runpy.py", line 193, in _run_module_as_main
    "__main__", mod_spec)
  File "/usr/lib/python3.6/runpy.py", line 85, in _run_code
    exec(code, run_globals)
  File "/usr/local/lib/python3.6/dist-packages/mpi4py/__main__.py", line 7, in <module>
    main()
  File "/usr/local/lib/python3.6/dist-packages/mpi4py/run.py", line 196, in main
    run_command_line(args)
  File "/usr/local/lib/python3.6/dist-packages/mpi4py/run.py", line 47, in run_command_line
    run_path(sys.argv[0], run_name='__main__')
  File "/usr/lib/python3.6/runpy.py", line 263, in run_path
    pkg_name=pkg_name, script_name=fname)
  File "/usr/lib/python3.6/runpy.py", line 96, in _run_module_code
    mod_name, mod_spec, pkg_name, script_name)
  File "/usr/lib/python3.6/runpy.py", line 85, in _run_code
    exec(code, run_globals)
  File "ga_wrapper.py", line 151, in <module>
    myFitness=getFitness(data,numStochasticReplicates,myIP)
  File "ga_wrapper.py", line 45, in getFitness
    fitness=np.zeros()
TypeError: Required argument 'shape' (pos 1) not found
Traceback (most recent call last):
  File "/usr/lib/python3.6/runpy.py", line 193, in _run_module_as_main
    "__main__", mod_spec)
  File "/usr/lib/python3.6/runpy.py", line 85, in _run_code
    exec(code, run_globals)
  File "/usr/local/lib/python3.6/dist-packages/mpi4py/__main__.py", line 7, in <module>
    main()
  File "/usr/local/lib/python3.6/dist-packages/mpi4py/run.py", line 196, in main
    run_command_line(args)
  File "/usr/local/lib/python3.6/dist-packages/mpi4py/run.py", line 47, in run_command_line
    run_path(sys.argv[0], run_name='__main__')
  File "/usr/lib/python3.6/runpy.py", line 263, in run_path
    pkg_name=pkg_name, script_name=fname)
  File "/usr/lib/python3.6/runpy.py", line 96, in _run_module_code
    mod_name, mod_spec, pkg_name, script_name)
  File "/usr/lib/python3.6/runpy.py", line 85, in _run_code
    exec(code, run_globals)
  File "ga_wrapper.py", line 151, in <module>
    myFitness=getFitness(data,numStochasticReplicates,myIP)
  File "ga_wrapper.py", line 45, in getFitness
    fitness=np.zeros()
TypeError: Required argument 'shape' (pos 1) not found
Traceback (most recent call last):
  File "/usr/lib/python3.6/runpy.py", line 193, in _run_module_as_main
    "__main__", mod_spec)
  File "/usr/lib/python3.6/runpy.py", line 85, in _run_code
    exec(code, run_globals)
  File "/usr/local/lib/python3.6/dist-packages/mpi4py/__main__.py", line 7, in <module>
    main()
  File "/usr/local/lib/python3.6/dist-packages/mpi4py/run.py", line 196, in main
    run_command_line(args)
  File "/usr/local/lib/python3.6/dist-packages/mpi4py/run.py", line 47, in run_command_line
    run_path(sys.argv[0], run_name='__main__')
  File "/usr/lib/python3.6/runpy.py", line 263, in run_path
    pkg_name=pkg_name, script_name=fname)
  File "/usr/lib/python3.6/runpy.py", line 96, in _run_module_code
    mod_name, mod_spec, pkg_name, script_name)
  File "/usr/lib/python3.6/runpy.py", line 85, in _run_code
    exec(code, run_globals)
  File "ga_wrapper.py", line 151, in <module>
    myFitness=getFitness(data,numStochasticReplicates,myIP)
  File "ga_wrapper.py", line 45, in getFitness
    fitness=np.zeros()
TypeError: Required argument 'shape' (pos 1) not found
Traceback (most recent call last):
  File "/usr/lib/python3.6/runpy.py", line 193, in _run_module_as_main
    "__main__", mod_spec)
  File "/usr/lib/python3.6/runpy.py", line 85, in _run_code
    exec(code, run_globals)
  File "/usr/local/lib/python3.6/dist-packages/mpi4py/__main__.py", line 7, in <module>
    main()
  File "/usr/local/lib/python3.6/dist-packages/mpi4py/run.py", line 196, in main
    run_command_line(args)
  File "/usr/local/lib/python3.6/dist-packages/mpi4py/run.py", line 47, in run_command_line
    run_path(sys.argv[0], run_name='__main__')
  File "/usr/lib/python3.6/runpy.py", line 263, in run_path
    pkg_name=pkg_name, script_name=fname)
  File "/usr/lib/python3.6/runpy.py", line 96, in _run_module_code
    mod_name, mod_spec, pkg_name, script_name)
  File "/usr/lib/python3.6/runpy.py", line 85, in _run_code
    exec(code, run_globals)
  File "ga_wrapper.py", line 151, in <module>
    myFitness=getFitness(data,numStochasticReplicates,myIP)
  File "ga_wrapper.py", line 45, in getFitness
    fitness=np.zeros()
TypeError: Required argument 'shape' (pos 1) not found
Traceback (most recent call last):
  File "/usr/lib/python3.6/runpy.py", line 193, in _run_module_as_main
    "__main__", mod_spec)
  File "/usr/lib/python3.6/runpy.py", line 85, in _run_code
    exec(code, run_globals)
  File "/usr/local/lib/python3.6/dist-packages/mpi4py/__main__.py", line 7, in <module>
    main()
  File "/usr/local/lib/python3.6/dist-packages/mpi4py/run.py", line 196, in main
    run_command_line(args)
  File "/usr/local/lib/python3.6/dist-packages/mpi4py/run.py", line 47, in run_command_line
    run_path(sys.argv[0], run_name='__main__')
  File "/usr/lib/python3.6/runpy.py", line 263, in run_path
    pkg_name=pkg_name, script_name=fname)
  File "/usr/lib/python3.6/runpy.py", line 96, in _run_module_code
    mod_name, mod_spec, pkg_name, script_name)
  File "/usr/lib/python3.6/runpy.py", line 85, in _run_code
    exec(code, run_globals)
  File "ga_wrapper.py", line 151, in <module>
    myFitness=getFitness(data,numStochasticReplicates,myIP)
  File "ga_wrapper.py", line 45, in getFitness
    fitness=np.zeros()
TypeError: Required argument 'shape' (pos 1) not found
Traceback (most recent call last):
  File "/usr/lib/python3.6/runpy.py", line 193, in _run_module_as_main
    "__main__", mod_spec)
  File "/usr/lib/python3.6/runpy.py", line 85, in _run_code
    exec(code, run_globals)
  File "/usr/local/lib/python3.6/dist-packages/mpi4py/__main__.py", line 7, in <module>
    main()
  File "/usr/local/lib/python3.6/dist-packages/mpi4py/run.py", line 196, in main
    run_command_line(args)
  File "/usr/local/lib/python3.6/dist-packages/mpi4py/run.py", line 47, in run_command_line
    run_path(sys.argv[0], run_name='__main__')
  File "/usr/lib/python3.6/runpy.py", line 263, in run_path
    pkg_name=pkg_name, script_name=fname)
  File "/usr/lib/python3.6/runpy.py", line 96, in _run_module_code
    mod_name, mod_spec, pkg_name, script_name)
  File "/usr/lib/python3.6/runpy.py", line 85, in _run_code
    exec(code, run_globals)
  File "ga_wrapper.py", line 151, in <module>
    myFitness=getFitness(data,numStochasticReplicates,myIP)
  File "ga_wrapper.py", line 45, in getFitness
    fitness=np.zeros()
TypeError: Required argument 'shape' (pos 1) not found
Traceback (most recent call last):
  File "/usr/lib/python3.6/runpy.py", line 193, in _run_module_as_main
    "__main__", mod_spec)
  File "/usr/lib/python3.6/runpy.py", line 85, in _run_code
    exec(code, run_globals)
  File "/usr/local/lib/python3.6/dist-packages/mpi4py/__main__.py", line 7, in <module>
    main()
  File "/usr/local/lib/python3.6/dist-packages/mpi4py/run.py", line 196, in main
    run_command_line(args)
  File "/usr/local/lib/python3.6/dist-packages/mpi4py/run.py", line 47, in run_command_line
    run_path(sys.argv[0], run_name='__main__')
  File "/usr/lib/python3.6/runpy.py", line 263, in run_path
    pkg_name=pkg_name, script_name=fname)
  File "/usr/lib/python3.6/runpy.py", line 96, in _run_module_code
    mod_name, mod_spec, pkg_name, script_name)
  File "/usr/lib/python3.6/runpy.py", line 85, in _run_code
    exec(code, run_globals)
  File "ga_wrapper.py", line 151, in <module>
    myFitness=getFitness(data,numStochasticReplicates,myIP)
  File "ga_wrapper.py", line 45, in getFitness
    fitness=np.zeros()
TypeError: Required argument 'shape' (pos 1) not found
Traceback (most recent call last):
  File "/usr/lib/python3.6/runpy.py", line 193, in _run_module_as_main
    "__main__", mod_spec)
  File "/usr/lib/python3.6/runpy.py", line 85, in _run_code
    exec(code, run_globals)
  File "/usr/local/lib/python3.6/dist-packages/mpi4py/__main__.py", line 7, in <module>
    main()
  File "/usr/local/lib/python3.6/dist-packages/mpi4py/run.py", line 196, in main
    run_command_line(args)
  File "/usr/local/lib/python3.6/dist-packages/mpi4py/run.py", line 47, in run_command_line
    run_path(sys.argv[0], run_name='__main__')
  File "/usr/lib/python3.6/runpy.py", line 263, in run_path
    pkg_name=pkg_name, script_name=fname)
  File "/usr/lib/python3.6/runpy.py", line 96, in _run_module_code
    mod_name, mod_spec, pkg_name, script_name)
  File "/usr/lib/python3.6/runpy.py", line 85, in _run_code
    exec(code, run_globals)
  File "ga_wrapper.py", line 151, in <module>
    myFitness=getFitness(data,numStochasticReplicates,myIP)
  File "ga_wrapper.py", line 45, in getFitness
    fitness=np.zeros()
TypeError: Required argument 'shape' (pos 1) not found
Traceback (most recent call last):
  File "/usr/lib/python3.6/runpy.py", line 193, in _run_module_as_main
    "__main__", mod_spec)
  File "/usr/lib/python3.6/runpy.py", line 85, in _run_code
    exec(code, run_globals)
  File "/usr/local/lib/python3.6/dist-packages/mpi4py/__main__.py", line 7, in <module>
    main()
  File "/usr/local/lib/python3.6/dist-packages/mpi4py/run.py", line 196, in main
    run_command_line(args)
  File "/usr/local/lib/python3.6/dist-packages/mpi4py/run.py", line 47, in run_command_line
    run_path(sys.argv[0], run_name='__main__')
  File "/usr/lib/python3.6/runpy.py", line 263, in run_path
    pkg_name=pkg_name, script_name=fname)
  File "/usr/lib/python3.6/runpy.py", line 96, in _run_module_code
    mod_name, mod_spec, pkg_name, script_name)
  File "/usr/lib/python3.6/runpy.py", line 85, in _run_code
    exec(code, run_globals)
  File "ga_wrapper.py", line 151, in <module>
    myFitness=getFitness(data,numStochasticReplicates,myIP)
  File "ga_wrapper.py", line 45, in getFitness
    fitness=np.zeros()
TypeError: Required argument 'shape' (pos 1) not found
Traceback (most recent call last):
  File "/usr/lib/python3.6/runpy.py", line 193, in _run_module_as_main
    "__main__", mod_spec)
  File "/usr/lib/python3.6/runpy.py", line 85, in _run_code
    exec(code, run_globals)
  File "/usr/local/lib/python3.6/dist-packages/mpi4py/__main__.py", line 7, in <module>
    main()
  File "/usr/local/lib/python3.6/dist-packages/mpi4py/run.py", line 196, in main
    run_command_line(args)
  File "/usr/local/lib/python3.6/dist-packages/mpi4py/run.py", line 47, in run_command_line
    run_path(sys.argv[0], run_name='__main__')
  File "/usr/lib/python3.6/runpy.py", line 263, in run_path
    pkg_name=pkg_name, script_name=fname)
  File "/usr/lib/python3.6/runpy.py", line 96, in _run_module_code
    mod_name, mod_spec, pkg_name, script_name)
  File "/usr/lib/python3.6/runpy.py", line 85, in _run_code
    exec(code, run_globals)
  File "ga_wrapper.py", line 151, in <module>
    myFitness=getFitness(data,numStochasticReplicates,myIP)
  File "ga_wrapper.py", line 45, in getFitness
    fitness=np.zeros()
TypeError: Required argument 'shape' (pos 1) not found
Traceback (most recent call last):
  File "/usr/lib/python3.6/runpy.py", line 193, in _run_module_as_main
    "__main__", mod_spec)
  File "/usr/lib/python3.6/runpy.py", line 85, in _run_code
    exec(code, run_globals)
  File "/usr/local/lib/python3.6/dist-packages/mpi4py/__main__.py", line 7, in <module>
    main()
  File "/usr/local/lib/python3.6/dist-packages/mpi4py/run.py", line 196, in main
    run_command_line(args)
  File "/usr/local/lib/python3.6/dist-packages/mpi4py/run.py", line 47, in run_command_line
    run_path(sys.argv[0], run_name='__main__')
  File "/usr/lib/python3.6/runpy.py", line 263, in run_path
    pkg_name=pkg_name, script_name=fname)
  File "/usr/lib/python3.6/runpy.py", line 96, in _run_module_code
    mod_name, mod_spec, pkg_name, script_name)
  File "/usr/lib/python3.6/runpy.py", line 85, in _run_code
    exec(code, run_globals)
  File "ga_wrapper.py", line 151, in <module>
    myFitness=getFitness(data,numStochasticReplicates,myIP)
  File "ga_wrapper.py", line 45, in getFitness
    fitness=np.zeros()
TypeError: Required argument 'shape' (pos 1) not found
Traceback (most recent call last):
  File "/usr/lib/python3.6/runpy.py", line 193, in _run_module_as_main
    "__main__", mod_spec)
  File "/usr/lib/python3.6/runpy.py", line 85, in _run_code
    exec(code, run_globals)
  File "/usr/local/lib/python3.6/dist-packages/mpi4py/__main__.py", line 7, in <module>
    main()
  File "/usr/local/lib/python3.6/dist-packages/mpi4py/run.py", line 196, in main
    run_command_line(args)
  File "/usr/local/lib/python3.6/dist-packages/mpi4py/run.py", line 47, in run_command_line
    run_path(sys.argv[0], run_name='__main__')
  File "/usr/lib/python3.6/runpy.py", line 263, in run_path
    pkg_name=pkg_name, script_name=fname)
  File "/usr/lib/python3.6/runpy.py", line 96, in _run_module_code
    mod_name, mod_spec, pkg_name, script_name)
  File "/usr/lib/python3.6/runpy.py", line 85, in _run_code
    exec(code, run_globals)
  File "ga_wrapper.py", line 151, in <module>
    myFitness=getFitness(data,numStochasticReplicates,myIP)
  File "ga_wrapper.py", line 45, in getFitness
    fitness=np.zeros()
TypeError: Required argument 'shape' (pos 1) not found
Traceback (most recent call last):
  File "/usr/lib/python3.6/runpy.py", line 193, in _run_module_as_main
    "__main__", mod_spec)
  File "/usr/lib/python3.6/runpy.py", line 85, in _run_code
    exec(code, run_globals)
  File "/usr/local/lib/python3.6/dist-packages/mpi4py/__main__.py", line 7, in <module>
    main()
  File "/usr/local/lib/python3.6/dist-packages/mpi4py/run.py", line 196, in main
    run_command_line(args)
  File "/usr/local/lib/python3.6/dist-packages/mpi4py/run.py", line 47, in run_command_line
    run_path(sys.argv[0], run_name='__main__')
  File "/usr/lib/python3.6/runpy.py", line 263, in run_path
    pkg_name=pkg_name, script_name=fname)
  File "/usr/lib/python3.6/runpy.py", line 96, in _run_module_code
    mod_name, mod_spec, pkg_name, script_name)
  File "/usr/lib/python3.6/runpy.py", line 85, in _run_code
    exec(code, run_globals)
  File "ga_wrapper.py", line 151, in <module>
    myFitness=getFitness(data,numStochasticReplicates,myIP)
  File "ga_wrapper.py", line 45, in getFitness
    fitness=np.zeros()
TypeError: Required argument 'shape' (pos 1) not found
Traceback (most recent call last):
  File "/usr/lib/python3.6/runpy.py", line 193, in _run_module_as_main
    "__main__", mod_spec)
  File "/usr/lib/python3.6/runpy.py", line 85, in _run_code
    exec(code, run_globals)
  File "/usr/local/lib/python3.6/dist-packages/mpi4py/__main__.py", line 7, in <module>
    main()
  File "/usr/local/lib/python3.6/dist-packages/mpi4py/run.py", line 196, in main
    run_command_line(args)
  File "/usr/local/lib/python3.6/dist-packages/mpi4py/run.py", line 47, in run_command_line
    run_path(sys.argv[0], run_name='__main__')
  File "/usr/lib/python3.6/runpy.py", line 263, in run_path
    pkg_name=pkg_name, script_name=fname)
  File "/usr/lib/python3.6/runpy.py", line 96, in _run_module_code
    mod_name, mod_spec, pkg_name, script_name)
  File "/usr/lib/python3.6/runpy.py", line 85, in _run_code
    exec(code, run_globals)
  File "ga_wrapper.py", line 151, in <module>
    myFitness=getFitness(data,numStochasticReplicates,myIP)
  File "ga_wrapper.py", line 45, in getFitness
    fitness=np.zeros()
TypeError: Required argument 'shape' (pos 1) not found
Traceback (most recent call last):
  File "/usr/lib/python3.6/runpy.py", line 193, in _run_module_as_main
    "__main__", mod_spec)
  File "/usr/lib/python3.6/runpy.py", line 85, in _run_code
    exec(code, run_globals)
  File "/usr/local/lib/python3.6/dist-packages/mpi4py/__main__.py", line 7, in <module>
    main()
  File "/usr/local/lib/python3.6/dist-packages/mpi4py/run.py", line 196, in main
    run_command_line(args)
  File "/usr/local/lib/python3.6/dist-packages/mpi4py/run.py", line 47, in run_command_line
    run_path(sys.argv[0], run_name='__main__')
  File "/usr/lib/python3.6/runpy.py", line 263, in run_path
    pkg_name=pkg_name, script_name=fname)
  File "/usr/lib/python3.6/runpy.py", line 96, in _run_module_code
    mod_name, mod_spec, pkg_name, script_name)
  File "/usr/lib/python3.6/runpy.py", line 85, in _run_code
    exec(code, run_globals)
  File "ga_wrapper.py", line 151, in <module>
    myFitness=getFitness(data,numStochasticReplicates,myIP)
  File "ga_wrapper.py", line 45, in getFitness
    fitness=np.zeros()
TypeError: Required argument 'shape' (pos 1) not found
Traceback (most recent call last):
  File "/usr/lib/python3.6/runpy.py", line 193, in _run_module_as_main
    "__main__", mod_spec)
  File "/usr/lib/python3.6/runpy.py", line 85, in _run_code
    exec(code, run_globals)
  File "/usr/local/lib/python3.6/dist-packages/mpi4py/__main__.py", line 7, in <module>
    main()
  File "/usr/local/lib/python3.6/dist-packages/mpi4py/run.py", line 196, in main
    run_command_line(args)
  File "/usr/local/lib/python3.6/dist-packages/mpi4py/run.py", line 47, in run_command_line
    run_path(sys.argv[0], run_name='__main__')
  File "/usr/lib/python3.6/runpy.py", line 263, in run_path
    pkg_name=pkg_name, script_name=fname)
  File "/usr/lib/python3.6/runpy.py", line 96, in _run_module_code
    mod_name, mod_spec, pkg_name, script_name)
  File "/usr/lib/python3.6/runpy.py", line 85, in _run_code
    exec(code, run_globals)
  File "ga_wrapper.py", line 151, in <module>
    myFitness=getFitness(data,numStochasticReplicates,myIP)
  File "ga_wrapper.py", line 45, in getFitness
    fitness=np.zeros()
TypeError: Required argument 'shape' (pos 1) not found
Traceback (most recent call last):
  File "/usr/lib/python3.6/runpy.py", line 193, in _run_module_as_main
    "__main__", mod_spec)
  File "/usr/lib/python3.6/runpy.py", line 85, in _run_code
    exec(code, run_globals)
  File "/usr/local/lib/python3.6/dist-packages/mpi4py/__main__.py", line 7, in <module>
    main()
  File "/usr/local/lib/python3.6/dist-packages/mpi4py/run.py", line 196, in main
    run_command_line(args)
  File "/usr/local/lib/python3.6/dist-packages/mpi4py/run.py", line 47, in run_command_line
    run_path(sys.argv[0], run_name='__main__')
  File "/usr/lib/python3.6/runpy.py", line 263, in run_path
    pkg_name=pkg_name, script_name=fname)
  File "/usr/lib/python3.6/runpy.py", line 96, in _run_module_code
    mod_name, mod_spec, pkg_name, script_name)
  File "/usr/lib/python3.6/runpy.py", line 85, in _run_code
    exec(code, run_globals)
  File "ga_wrapper.py", line 151, in <module>
    myFitness=getFitness(data,numStochasticReplicates,myIP)
  File "ga_wrapper.py", line 45, in getFitness
    fitness=np.zeros()
TypeError: Required argument 'shape' (pos 1) not found
--------------------------------------------------------------------------
MPI_ABORT was invoked on rank 27 in communicator MPI_COMM_WORLD
with errorcode 1.

NOTE: invoking MPI_ABORT causes Open MPI to kill all MPI processes.
You may or may not see output from other processes, depending on
exactly when Open MPI kills them.
--------------------------------------------------------------------------
Traceback (most recent call last):
  File "/usr/lib/python3.6/runpy.py", line 193, in _run_module_as_main
    "__main__", mod_spec)
  File "/usr/lib/python3.6/runpy.py", line 85, in _run_code
    exec(code, run_globals)
  File "/usr/local/lib/python3.6/dist-packages/mpi4py/__main__.py", line 7, in <module>
    main()
  File "/usr/local/lib/python3.6/dist-packages/mpi4py/run.py", line 196, in main
    run_command_line(args)
  File "/usr/local/lib/python3.6/dist-packages/mpi4py/run.py", line 47, in run_command_line
    run_path(sys.argv[0], run_name='__main__')
  File "/usr/lib/python3.6/runpy.py", line 263, in run_path
    pkg_name=pkg_name, script_name=fname)
  File "/usr/lib/python3.6/runpy.py", line 96, in _run_module_code
    mod_name, mod_spec, pkg_name, script_name)
  File "/usr/lib/python3.6/runpy.py", line 85, in _run_code
    exec(code, run_globals)
  File "ga_wrapper.py", line 151, in <module>
    myFitness=getFitness(data,numStochasticReplicates,myIP)
  File "ga_wrapper.py", line 45, in getFitness
    fitness=np.zeros()
TypeError: Required argument 'shape' (pos 1) not found
Traceback (most recent call last):
  File "/usr/lib/python3.6/runpy.py", line 193, in _run_module_as_main
    "__main__", mod_spec)
  File "/usr/lib/python3.6/runpy.py", line 85, in _run_code
    exec(code, run_globals)
  File "/usr/local/lib/python3.6/dist-packages/mpi4py/__main__.py", line 7, in <module>
    main()
  File "/usr/local/lib/python3.6/dist-packages/mpi4py/run.py", line 196, in main
    run_command_line(args)
  File "/usr/local/lib/python3.6/dist-packages/mpi4py/run.py", line 47, in run_command_line
    run_path(sys.argv[0], run_name='__main__')
  File "/usr/lib/python3.6/runpy.py", line 263, in run_path
    pkg_name=pkg_name, script_name=fname)
  File "/usr/lib/python3.6/runpy.py", line 96, in _run_module_code
    mod_name, mod_spec, pkg_name, script_name)
  File "/usr/lib/python3.6/runpy.py", line 85, in _run_code
    exec(code, run_globals)
  File "ga_wrapper.py", line 151, in <module>
    myFitness=getFitness(data,numStochasticReplicates,myIP)
  File "ga_wrapper.py", line 45, in getFitness
    fitness=np.zeros()
TypeError: Required argument 'shape' (pos 1) not found
Traceback (most recent call last):
  File "/usr/lib/python3.6/runpy.py", line 193, in _run_module_as_main
    "__main__", mod_spec)
  File "/usr/lib/python3.6/runpy.py", line 85, in _run_code
    exec(code, run_globals)
  File "/usr/local/lib/python3.6/dist-packages/mpi4py/__main__.py", line 7, in <module>
    main()
  File "/usr/local/lib/python3.6/dist-packages/mpi4py/run.py", line 196, in main
    run_command_line(args)
  File "/usr/local/lib/python3.6/dist-packages/mpi4py/run.py", line 47, in run_command_line
    run_path(sys.argv[0], run_name='__main__')
  File "/usr/lib/python3.6/runpy.py", line 263, in run_path
    pkg_name=pkg_name, script_name=fname)
  File "/usr/lib/python3.6/runpy.py", line 96, in _run_module_code
    mod_name, mod_spec, pkg_name, script_name)
  File "/usr/lib/python3.6/runpy.py", line 85, in _run_code
    exec(code, run_globals)
  File "ga_wrapper.py", line 151, in <module>
    myFitness=getFitness(data,numStochasticReplicates,myIP)
  File "ga_wrapper.py", line 45, in getFitness
    fitness=np.zeros()
TypeError: Required argument 'shape' (pos 1) not found
Traceback (most recent call last):
  File "/usr/lib/python3.6/runpy.py", line 193, in _run_module_as_main
    "__main__", mod_spec)
  File "/usr/lib/python3.6/runpy.py", line 85, in _run_code
    exec(code, run_globals)
  File "/usr/local/lib/python3.6/dist-packages/mpi4py/__main__.py", line 7, in <module>
    main()
  File "/usr/local/lib/python3.6/dist-packages/mpi4py/run.py", line 196, in main
    run_command_line(args)
  File "/usr/local/lib/python3.6/dist-packages/mpi4py/run.py", line 47, in run_command_line
    run_path(sys.argv[0], run_name='__main__')
  File "/usr/lib/python3.6/runpy.py", line 263, in run_path
    pkg_name=pkg_name, script_name=fname)
  File "/usr/lib/python3.6/runpy.py", line 96, in _run_module_code
    mod_name, mod_spec, pkg_name, script_name)
  File "/usr/lib/python3.6/runpy.py", line 85, in _run_code
    exec(code, run_globals)
  File "ga_wrapper.py", line 151, in <module>
    myFitness=getFitness(data,numStochasticReplicates,myIP)
  File "ga_wrapper.py", line 45, in getFitness
    fitness=np.zeros()
TypeError: Required argument 'shape' (pos 1) not found
Traceback (most recent call last):
  File "/usr/lib/python3.6/runpy.py", line 193, in _run_module_as_main
    "__main__", mod_spec)
  File "/usr/lib/python3.6/runpy.py", line 85, in _run_code
    exec(code, run_globals)
  File "/usr/local/lib/python3.6/dist-packages/mpi4py/__main__.py", line 7, in <module>
    main()
  File "/usr/local/lib/python3.6/dist-packages/mpi4py/run.py", line 196, in main
    run_command_line(args)
  File "/usr/local/lib/python3.6/dist-packages/mpi4py/run.py", line 47, in run_command_line
    run_path(sys.argv[0], run_name='__main__')
  File "/usr/lib/python3.6/runpy.py", line 263, in run_path
    pkg_name=pkg_name, script_name=fname)
  File "/usr/lib/python3.6/runpy.py", line 96, in _run_module_code
    mod_name, mod_spec, pkg_name, script_name)
  File "/usr/lib/python3.6/runpy.py", line 85, in _run_code
    exec(code, run_globals)
  File "ga_wrapper.py", line 151, in <module>
    myFitness=getFitness(data,numStochasticReplicates,myIP)
  File "ga_wrapper.py", line 45, in getFitness
    fitness=np.zeros()
TypeError: Required argument 'shape' (pos 1) not found
Traceback (most recent call last):
  File "/usr/lib/python3.6/runpy.py", line 193, in _run_module_as_main
    "__main__", mod_spec)
  File "/usr/lib/python3.6/runpy.py", line 85, in _run_code
    exec(code, run_globals)
  File "/usr/local/lib/python3.6/dist-packages/mpi4py/__main__.py", line 7, in <module>
    main()
  File "/usr/local/lib/python3.6/dist-packages/mpi4py/run.py", line 196, in main
    run_command_line(args)
  File "/usr/local/lib/python3.6/dist-packages/mpi4py/run.py", line 47, in run_command_line
    run_path(sys.argv[0], run_name='__main__')
  File "/usr/lib/python3.6/runpy.py", line 263, in run_path
    pkg_name=pkg_name, script_name=fname)
  File "/usr/lib/python3.6/runpy.py", line 96, in _run_module_code
    mod_name, mod_spec, pkg_name, script_name)
  File "/usr/lib/python3.6/runpy.py", line 85, in _run_code
    exec(code, run_globals)
  File "ga_wrapper.py", line 151, in <module>
    myFitness=getFitness(data,numStochasticReplicates,myIP)
  File "ga_wrapper.py", line 45, in getFitness
    fitness=np.zeros()
TypeError: Required argument 'shape' (pos 1) not found
Traceback (most recent call last):
  File "/usr/lib/python3.6/runpy.py", line 193, in _run_module_as_main
    "__main__", mod_spec)
  File "/usr/lib/python3.6/runpy.py", line 85, in _run_code
    exec(code, run_globals)
  File "/usr/local/lib/python3.6/dist-packages/mpi4py/__main__.py", line 7, in <module>
    main()
  File "/usr/local/lib/python3.6/dist-packages/mpi4py/run.py", line 196, in main
    run_command_line(args)
  File "/usr/local/lib/python3.6/dist-packages/mpi4py/run.py", line 47, in run_command_line
    run_path(sys.argv[0], run_name='__main__')
  File "/usr/lib/python3.6/runpy.py", line 263, in run_path
    pkg_name=pkg_name, script_name=fname)
  File "/usr/lib/python3.6/runpy.py", line 96, in _run_module_code
    mod_name, mod_spec, pkg_name, script_name)
  File "/usr/lib/python3.6/runpy.py", line 85, in _run_code
    exec(code, run_globals)
  File "ga_wrapper.py", line 151, in <module>
    myFitness=getFitness(data,numStochasticReplicates,myIP)
  File "ga_wrapper.py", line 45, in getFitness
    fitness=np.zeros()
TypeError: Required argument 'shape' (pos 1) not found
Traceback (most recent call last):
  File "/usr/lib/python3.6/runpy.py", line 193, in _run_module_as_main
    "__main__", mod_spec)
  File "/usr/lib/python3.6/runpy.py", line 85, in _run_code
    exec(code, run_globals)
  File "/usr/local/lib/python3.6/dist-packages/mpi4py/__main__.py", line 7, in <module>
    main()
  File "/usr/local/lib/python3.6/dist-packages/mpi4py/run.py", line 196, in main
    run_command_line(args)
  File "/usr/local/lib/python3.6/dist-packages/mpi4py/run.py", line 47, in run_command_line
    run_path(sys.argv[0], run_name='__main__')
  File "/usr/lib/python3.6/runpy.py", line 263, in run_path
    pkg_name=pkg_name, script_name=fname)
  File "/usr/lib/python3.6/runpy.py", line 96, in _run_module_code
    mod_name, mod_spec, pkg_name, script_name)
  File "/usr/lib/python3.6/runpy.py", line 85, in _run_code
    exec(code, run_globals)
  File "ga_wrapper.py", line 151, in <module>
    myFitness=getFitness(data,numStochasticReplicates,myIP)
  File "ga_wrapper.py", line 45, in getFitness
    fitness=np.zeros()
TypeError: Required argument 'shape' (pos 1) not found
Traceback (most recent call last):
  File "/usr/lib/python3.6/runpy.py", line 193, in _run_module_as_main
    "__main__", mod_spec)
  File "/usr/lib/python3.6/runpy.py", line 85, in _run_code
    exec(code, run_globals)
  File "/usr/local/lib/python3.6/dist-packages/mpi4py/__main__.py", line 7, in <module>
    main()
  File "/usr/local/lib/python3.6/dist-packages/mpi4py/run.py", line 196, in main
    run_command_line(args)
  File "/usr/local/lib/python3.6/dist-packages/mpi4py/run.py", line 47, in run_command_line
    run_path(sys.argv[0], run_name='__main__')
  File "/usr/lib/python3.6/runpy.py", line 263, in run_path
    pkg_name=pkg_name, script_name=fname)
  File "/usr/lib/python3.6/runpy.py", line 96, in _run_module_code
    mod_name, mod_spec, pkg_name, script_name)
  File "/usr/lib/python3.6/runpy.py", line 85, in _run_code
    exec(code, run_globals)
  File "ga_wrapper.py", line 151, in <module>
    myFitness=getFitness(data,numStochasticReplicates,myIP)
  File "ga_wrapper.py", line 45, in getFitness
    fitness=np.zeros()
TypeError: Required argument 'shape' (pos 1) not found
Traceback (most recent call last):
  File "/usr/lib/python3.6/runpy.py", line 193, in _run_module_as_main
    "__main__", mod_spec)
  File "/usr/lib/python3.6/runpy.py", line 85, in _run_code
    exec(code, run_globals)
  File "/usr/local/lib/python3.6/dist-packages/mpi4py/__main__.py", line 7, in <module>
    main()
  File "/usr/local/lib/python3.6/dist-packages/mpi4py/run.py", line 196, in main
    run_command_line(args)
  File "/usr/local/lib/python3.6/dist-packages/mpi4py/run.py", line 47, in run_command_line
    run_path(sys.argv[0], run_name='__main__')
  File "/usr/lib/python3.6/runpy.py", line 263, in run_path
    pkg_name=pkg_name, script_name=fname)
  File "/usr/lib/python3.6/runpy.py", line 96, in _run_module_code
    mod_name, mod_spec, pkg_name, script_name)
  File "/usr/lib/python3.6/runpy.py", line 85, in _run_code
    exec(code, run_globals)
  File "ga_wrapper.py", line 151, in <module>
    myFitness=getFitness(data,numStochasticReplicates,myIP)
  File "ga_wrapper.py", line 45, in getFitness
    fitness=np.zeros()
TypeError: Required argument 'shape' (pos 1) not found
Traceback (most recent call last):
  File "/usr/lib/python3.6/runpy.py", line 193, in _run_module_as_main
    "__main__", mod_spec)
  File "/usr/lib/python3.6/runpy.py", line 85, in _run_code
    exec(code, run_globals)
  File "/usr/local/lib/python3.6/dist-packages/mpi4py/__main__.py", line 7, in <module>
    main()
  File "/usr/local/lib/python3.6/dist-packages/mpi4py/run.py", line 196, in main
    run_command_line(args)
  File "/usr/local/lib/python3.6/dist-packages/mpi4py/run.py", line 47, in run_command_line
    run_path(sys.argv[0], run_name='__main__')
  File "/usr/lib/python3.6/runpy.py", line 263, in run_path
    pkg_name=pkg_name, script_name=fname)
  File "/usr/lib/python3.6/runpy.py", line 96, in _run_module_code
    mod_name, mod_spec, pkg_name, script_name)
  File "/usr/lib/python3.6/runpy.py", line 85, in _run_code
    exec(code, run_globals)
  File "ga_wrapper.py", line 151, in <module>
    myFitness=getFitness(data,numStochasticReplicates,myIP)
  File "ga_wrapper.py", line 45, in getFitness
    fitness=np.zeros()
TypeError: Required argument 'shape' (pos 1) not found
Traceback (most recent call last):
  File "/usr/lib/python3.6/runpy.py", line 193, in _run_module_as_main
    "__main__", mod_spec)
  File "/usr/lib/python3.6/runpy.py", line 85, in _run_code
    exec(code, run_globals)
  File "/usr/local/lib/python3.6/dist-packages/mpi4py/__main__.py", line 7, in <module>
    main()
  File "/usr/local/lib/python3.6/dist-packages/mpi4py/run.py", line 196, in main
    run_command_line(args)
  File "/usr/local/lib/python3.6/dist-packages/mpi4py/run.py", line 47, in run_command_line
    run_path(sys.argv[0], run_name='__main__')
  File "/usr/lib/python3.6/runpy.py", line 263, in run_path
    pkg_name=pkg_name, script_name=fname)
  File "/usr/lib/python3.6/runpy.py", line 96, in _run_module_code
    mod_name, mod_spec, pkg_name, script_name)
  File "/usr/lib/python3.6/runpy.py", line 85, in _run_code
    exec(code, run_globals)
  File "ga_wrapper.py", line 151, in <module>
    myFitness=getFitness(data,numStochasticReplicates,myIP)
  File "ga_wrapper.py", line 45, in getFitness
    fitness=np.zeros()
TypeError: Required argument 'shape' (pos 1) not found
Traceback (most recent call last):
  File "/usr/lib/python3.6/runpy.py", line 193, in _run_module_as_main
    "__main__", mod_spec)
  File "/usr/lib/python3.6/runpy.py", line 85, in _run_code
    exec(code, run_globals)
  File "/usr/local/lib/python3.6/dist-packages/mpi4py/__main__.py", line 7, in <module>
    main()
  File "/usr/local/lib/python3.6/dist-packages/mpi4py/run.py", line 196, in main
    run_command_line(args)
  File "/usr/local/lib/python3.6/dist-packages/mpi4py/run.py", line 47, in run_command_line
    run_path(sys.argv[0], run_name='__main__')
  File "/usr/lib/python3.6/runpy.py", line 263, in run_path
    pkg_name=pkg_name, script_name=fname)
  File "/usr/lib/python3.6/runpy.py", line 96, in _run_module_code
    mod_name, mod_spec, pkg_name, script_name)
  File "/usr/lib/python3.6/runpy.py", line 85, in _run_code
    exec(code, run_globals)
  File "ga_wrapper.py", line 151, in <module>
    myFitness=getFitness(data,numStochasticReplicates,myIP)
  File "ga_wrapper.py", line 45, in getFitness
    fitness=np.zeros()
TypeError: Required argument 'shape' (pos 1) not found
Traceback (most recent call last):
  File "/usr/lib/python3.6/runpy.py", line 193, in _run_module_as_main
    "__main__", mod_spec)
  File "/usr/lib/python3.6/runpy.py", line 85, in _run_code
    exec(code, run_globals)
  File "/usr/local/lib/python3.6/dist-packages/mpi4py/__main__.py", line 7, in <module>
    main()
  File "/usr/local/lib/python3.6/dist-packages/mpi4py/run.py", line 196, in main
    run_command_line(args)
  File "/usr/local/lib/python3.6/dist-packages/mpi4py/run.py", line 47, in run_command_line
    run_path(sys.argv[0], run_name='__main__')
  File "/usr/lib/python3.6/runpy.py", line 263, in run_path
    pkg_name=pkg_name, script_name=fname)
  File "/usr/lib/python3.6/runpy.py", line 96, in _run_module_code
    mod_name, mod_spec, pkg_name, script_name)
  File "/usr/lib/python3.6/runpy.py", line 85, in _run_code
    exec(code, run_globals)
  File "ga_wrapper.py", line 151, in <module>
    myFitness=getFitness(data,numStochasticReplicates,myIP)
  File "ga_wrapper.py", line 45, in getFitness
    fitness=np.zeros()
TypeError: Required argument 'shape' (pos 1) not found
[bastet:85577] 59 more processes have sent help message help-mpi-btl-base.txt / btl:no-nics
[bastet:85577] Set MCA parameter "orte_base_help_aggregate" to 0 to see all help / error messages
[bastet:85577] 3 more processes have sent help message help-mpi-api.txt / mpi-abort
